{
  "total_tests_checked": 18,
  "total_failures_found": 8,
  "failures_by_category": {
    "pinecone_namespace_cleanup": 1,
    "pinecone_other": 2,
    "neo4j_return_type": 1,
    "neo4j_other": 0,
    "transaction_consistency": 0,
    "transaction_integration": 4,
    "transaction_other": 0,
    "other": 0
  },
  "detailed_failures": {
    "pinecone_namespace_cleanup": [
      {
        "test_path": "tests/storage/test_pinecone_adapter.py::TestPineconeAdapter::test_search_with_filters",
        "return_code": 1,
        "passed": false,
        "stdout": "============================= test session starts ==============================\nplatform linux -- Python 3.12.8, pytest-8.4.1, pluggy-1.6.0 -- /home/ubuntu/.pyenv/versions/3.12.8/bin/python\ncachedir: .pytest_cache\nrootdir: /home/ubuntu/repos/NodeRAG\nconfigfile: pyproject.toml\nplugins: langsmith-0.4.4, rerunfailures-15.1, dash-3.1.1, Faker-18.13.0, anyio-4.8.0, asyncio-0.26.0, cov-6.2.1\nasyncio: mode=Mode.AUTO, asyncio_default_fixture_loop_scope=None, asyncio_default_test_loop_scope=function\ncollecting ... collected 1 item\n\ntests/storage/test_pinecone_adapter.py::TestPineconeAdapter::test_search_with_filters FAILED [100%]\n\n=================================== FAILURES ===================================\n_________________ TestPineconeAdapter.test_search_with_filters _________________\ntests/storage/test_pinecone_adapter.py:211: in test_search_with_filters\n    assert len(results) >= 1\nE   assert 0 >= 1\nE    +  where 0 = len([])\n----------------------------- Captured stdout call -----------------------------\nSearch results: []\nLooking for vector1_id: search_test_1\nSearch filters: tenant_id=test_tenant, interaction_type=email\nAll results in test_tenant: []\n---------------------------- Captured log teardown -----------------------------\nERROR    NodeRAG.storage.pinecone_adapter:pinecone_adapter.py:262 Failed to delete namespace test_tenant_1: (404)\nReason: Not Found\nHTTP response headers: HTTPHeaderDict({'Date': 'Sun, 03 Aug 2025 19:53:39 GMT', 'Content-Type': 'application/json', 'Content-Length': '55', 'Connection': 'keep-alive', 'x-pinecone-request-latency-ms': '1', 'x-pinecone-request-id': '6994322872857428948', 'x-envoy-upstream-service-time': '2', 'server': 'envoy'})\nHTTP response body: {\"code\":5,\"message\":\"Namespace not found\",\"details\":[]}\n\nERROR    NodeRAG.storage.pinecone_adapter:pinecone_adapter.py:262 Failed to delete namespace test_tenant_2: (404)\nReason: Not Found\nHTTP response headers: HTTPHeaderDict({'Date': 'Sun, 03 Aug 2025 19:53:39 GMT', 'Content-Type': 'application/json', 'Content-Length': '55', 'Connection': 'keep-alive', 'x-pinecone-request-latency-ms': '2', 'x-pinecone-request-id': '6051191404995970916', 'x-envoy-upstream-service-time': '2', 'server': 'envoy'})\nHTTP response body: {\"code\":5,\"message\":\"Namespace not found\",\"details\":[]}\n=========================== short test summary info ============================\nFAILED tests/storage/test_pinecone_adapter.py::TestPineconeAdapter::test_search_with_filters\n============================== 1 failed in 23.79s ==============================\n",
        "stderr": "",
        "error_summary": "Namespace not found"
      }
    ],
    "pinecone_other": [
      {
        "test_path": "tests/storage/test_pinecone_adapter.py::TestPineconeAdapter::test_upsert_vectors",
        "return_code": 4,
        "passed": false,
        "stdout": "============================= test session starts ==============================\nplatform linux -- Python 3.12.8, pytest-8.4.1, pluggy-1.6.0 -- /home/ubuntu/.pyenv/versions/3.12.8/bin/python\ncachedir: .pytest_cache\nrootdir: /home/ubuntu/repos/NodeRAG\nconfigfile: pyproject.toml\nplugins: langsmith-0.4.4, rerunfailures-15.1, dash-3.1.1, Faker-18.13.0, anyio-4.8.0, asyncio-0.26.0, cov-6.2.1\nasyncio: mode=Mode.AUTO, asyncio_default_fixture_loop_scope=None, asyncio_default_test_loop_scope=function\ncollecting ... collected 0 items\n\n============================ no tests ran in 2.21s =============================\n",
        "stderr": "ERROR: not found: /home/ubuntu/repos/NodeRAG/tests/storage/test_pinecone_adapter.py::TestPineconeAdapter::test_upsert_vectors\n(no match in any of [<Class TestPineconeAdapter>])\n\n",
        "error_summary": "No specific error pattern found"
      },
      {
        "test_path": "tests/integration/test_pinecone_integration.py",
        "return_code": -1,
        "passed": false,
        "stdout": "",
        "stderr": "Test timed out after 30 seconds",
        "error_summary": "Test timeout - likely connection or hanging issue"
      }
    ],
    "neo4j_return_type": [
      {
        "test_path": "tests/storage/test_neo4j_adapter.py::TestNeo4jAdapter::test_clear_tenant_data",
        "return_code": 1,
        "passed": false,
        "stdout": "============================= test session starts ==============================\nplatform linux -- Python 3.12.8, pytest-8.4.1, pluggy-1.6.0 -- /home/ubuntu/.pyenv/versions/3.12.8/bin/python\ncachedir: .pytest_cache\nrootdir: /home/ubuntu/repos/NodeRAG\nconfigfile: pyproject.toml\nplugins: langsmith-0.4.4, rerunfailures-15.1, dash-3.1.1, Faker-18.13.0, anyio-4.8.0, asyncio-0.26.0, cov-6.2.1\nasyncio: mode=Mode.AUTO, asyncio_default_fixture_loop_scope=None, asyncio_default_test_loop_scope=function\ncollecting ... collected 1 item\n\ntests/storage/test_neo4j_adapter.py::TestNeo4jAdapter::test_clear_tenant_data FAILED [100%]\n\n=================================== FAILURES ===================================\n___________________ TestNeo4jAdapter.test_clear_tenant_data ____________________\ntests/storage/test_neo4j_adapter.py:212: in test_clear_tenant_data\n    assert success is True\nE   assert (0, 0) is True\n=========================== short test summary info ============================\nFAILED tests/storage/test_neo4j_adapter.py::TestNeo4jAdapter::test_clear_tenant_data\n============================== 1 failed in 4.75s ===============================\n",
        "stderr": "",
        "error_summary": "assert success is True"
      }
    ],
    "neo4j_other": [],
    "transaction_consistency": [],
    "transaction_integration": [
      {
        "test_path": "tests/storage/test_transaction_integration.py::TestTransactionIntegration::test_successful_node_and_embedding_creation",
        "return_code": 1,
        "passed": false,
        "stdout": "============================= test session starts ==============================\nplatform linux -- Python 3.12.8, pytest-8.4.1, pluggy-1.6.0 -- /home/ubuntu/.pyenv/versions/3.12.8/bin/python\ncachedir: .pytest_cache\nrootdir: /home/ubuntu/repos/NodeRAG\nconfigfile: pyproject.toml\nplugins: langsmith-0.4.4, rerunfailures-15.1, dash-3.1.1, Faker-18.13.0, anyio-4.8.0, asyncio-0.26.0, cov-6.2.1\nasyncio: mode=Mode.AUTO, asyncio_default_fixture_loop_scope=None, asyncio_default_test_loop_scope=function\ncollecting ... collected 1 item\n\ntests/storage/test_transaction_integration.py::TestTransactionIntegration::test_successful_node_and_embedding_creation FAILED [100%]\n\n=================================== FAILURES ===================================\n____ TestTransactionIntegration.test_successful_node_and_embedding_creation ____\n../../.pyenv/versions/3.12.8/lib/python3.12/site-packages/pytest_asyncio/plugin.py:549: in runtest\n    super().runtest()\n../../.pyenv/versions/3.12.8/lib/python3.12/site-packages/pytest_asyncio/plugin.py:1066: in inner\n    _loop = _get_event_loop_no_warn()\n            ^^^^^^^^^^^^^^^^^^^^^^^^^\n../../.pyenv/versions/3.12.8/lib/python3.12/site-packages/pytest_asyncio/plugin.py:996: in _get_event_loop_no_warn\n    return asyncio.get_event_loop()\n           ^^^^^^^^^^^^^^^^^^^^^^^^\n../../.pyenv/versions/3.12.8/lib/python3.12/asyncio/events.py:702: in get_event_loop\n    raise RuntimeError('There is no current event loop in thread %r.'\nE   RuntimeError: There is no current event loop in thread 'MainThread'.\n------------------------------ Captured log setup ------------------------------\nERROR    NodeRAG.storage.pinecone_adapter:pinecone_adapter.py:262 Failed to delete namespace txn_test_tenant: (404)\nReason: Not Found\nHTTP response headers: HTTPHeaderDict({'Date': 'Sun, 03 Aug 2025 19:54:04 GMT', 'Content-Type': 'application/json', 'Content-Length': '55', 'Connection': 'keep-alive', 'x-pinecone-request-latency-ms': '23', 'x-pinecone-request-id': '4418735150012489711', 'x-envoy-upstream-service-time': '24', 'server': 'envoy'})\nHTTP response body: {\"code\":5,\"message\":\"Namespace not found\",\"details\":[]}\n---------------------------- Captured log teardown -----------------------------\nERROR    NodeRAG.storage.pinecone_adapter:pinecone_adapter.py:262 Failed to delete namespace txn_test_tenant: (404)\nReason: Not Found\nHTTP response headers: HTTPHeaderDict({'Date': 'Sun, 03 Aug 2025 19:54:04 GMT', 'Content-Type': 'application/json', 'Content-Length': '55', 'Connection': 'keep-alive', 'x-pinecone-request-latency-ms': '19', 'x-pinecone-request-id': '8894724315327290894', 'x-envoy-upstream-service-time': '19', 'server': 'envoy'})\nHTTP response body: {\"code\":5,\"message\":\"Namespace not found\",\"details\":[]}\n=============================== warnings summary ===============================\ntests/storage/test_transaction_integration.py:89\n  /home/ubuntu/repos/NodeRAG/tests/storage/test_transaction_integration.py:89: PytestUnknownMarkWarning: Unknown pytest.mark.integration - is this a typo?  You can register custom marks to avoid this warning - for details, see https://docs.pytest.org/en/stable/how-to/mark.html\n    @pytest.mark.integration\n\n-- Docs: https://docs.pytest.org/en/stable/how-to/capture-warnings.html\n=========================== short test summary info ============================\nFAILED tests/storage/test_transaction_integration.py::TestTransactionIntegration::test_successful_node_and_embedding_creation\n========================= 1 failed, 1 warning in 4.70s =========================\n",
        "stderr": "sys:1: RuntimeWarning: coroutine 'TestTransactionIntegration.test_successful_node_and_embedding_creation' was never awaited\n",
        "error_summary": "RuntimeError: There is no current event loop in thread 'MainThread'."
      },
      {
        "test_path": "tests/storage/test_transaction_integration.py::TestTransactionIntegration::test_batch_transaction_success",
        "return_code": 1,
        "passed": false,
        "stdout": "============================= test session starts ==============================\nplatform linux -- Python 3.12.8, pytest-8.4.1, pluggy-1.6.0 -- /home/ubuntu/.pyenv/versions/3.12.8/bin/python\ncachedir: .pytest_cache\nrootdir: /home/ubuntu/repos/NodeRAG\nconfigfile: pyproject.toml\nplugins: langsmith-0.4.4, rerunfailures-15.1, dash-3.1.1, Faker-18.13.0, anyio-4.8.0, asyncio-0.26.0, cov-6.2.1\nasyncio: mode=Mode.AUTO, asyncio_default_fixture_loop_scope=None, asyncio_default_test_loop_scope=function\ncollecting ... collected 1 item\n\ntests/storage/test_transaction_integration.py::TestTransactionIntegration::test_batch_transaction_success FAILED [100%]\n\n=================================== FAILURES ===================================\n__________ TestTransactionIntegration.test_batch_transaction_success ___________\n../../.pyenv/versions/3.12.8/lib/python3.12/site-packages/pytest_asyncio/plugin.py:549: in runtest\n    super().runtest()\n../../.pyenv/versions/3.12.8/lib/python3.12/site-packages/pytest_asyncio/plugin.py:1066: in inner\n    _loop = _get_event_loop_no_warn()\n            ^^^^^^^^^^^^^^^^^^^^^^^^^\n../../.pyenv/versions/3.12.8/lib/python3.12/site-packages/pytest_asyncio/plugin.py:996: in _get_event_loop_no_warn\n    return asyncio.get_event_loop()\n           ^^^^^^^^^^^^^^^^^^^^^^^^\n../../.pyenv/versions/3.12.8/lib/python3.12/asyncio/events.py:702: in get_event_loop\n    raise RuntimeError('There is no current event loop in thread %r.'\nE   RuntimeError: There is no current event loop in thread 'MainThread'.\n------------------------------ Captured log setup ------------------------------\nERROR    NodeRAG.storage.pinecone_adapter:pinecone_adapter.py:262 Failed to delete namespace txn_test_tenant: (404)\nReason: Not Found\nHTTP response headers: HTTPHeaderDict({'Date': 'Sun, 03 Aug 2025 19:54:14 GMT', 'Content-Type': 'application/json', 'Content-Length': '55', 'Connection': 'keep-alive', 'x-pinecone-request-latency-ms': '1', 'x-pinecone-request-id': '1675310034042861668', 'x-envoy-upstream-service-time': '2', 'server': 'envoy'})\nHTTP response body: {\"code\":5,\"message\":\"Namespace not found\",\"details\":[]}\n---------------------------- Captured log teardown -----------------------------\nERROR    NodeRAG.storage.pinecone_adapter:pinecone_adapter.py:262 Failed to delete namespace txn_test_tenant: (404)\nReason: Not Found\nHTTP response headers: HTTPHeaderDict({'Date': 'Sun, 03 Aug 2025 19:54:14 GMT', 'Content-Type': 'application/json', 'Content-Length': '55', 'Connection': 'keep-alive', 'x-pinecone-request-latency-ms': '3', 'x-pinecone-request-id': '9147613141540617540', 'x-envoy-upstream-service-time': '4', 'server': 'envoy'})\nHTTP response body: {\"code\":5,\"message\":\"Namespace not found\",\"details\":[]}\n=============================== warnings summary ===============================\ntests/storage/test_transaction_integration.py:89\n  /home/ubuntu/repos/NodeRAG/tests/storage/test_transaction_integration.py:89: PytestUnknownMarkWarning: Unknown pytest.mark.integration - is this a typo?  You can register custom marks to avoid this warning - for details, see https://docs.pytest.org/en/stable/how-to/mark.html\n    @pytest.mark.integration\n\n-- Docs: https://docs.pytest.org/en/stable/how-to/capture-warnings.html\n=========================== short test summary info ============================\nFAILED tests/storage/test_transaction_integration.py::TestTransactionIntegration::test_batch_transaction_success\n========================= 1 failed, 1 warning in 7.23s =========================\n",
        "stderr": "sys:1: RuntimeWarning: coroutine 'TestTransactionIntegration.test_batch_transaction_success' was never awaited\n",
        "error_summary": "RuntimeError: There is no current event loop in thread 'MainThread'."
      },
      {
        "test_path": "tests/storage/test_transaction_integration.py::TestTransactionIntegration::test_rollback_on_pinecone_failure",
        "return_code": 1,
        "passed": false,
        "stdout": "============================= test session starts ==============================\nplatform linux -- Python 3.12.8, pytest-8.4.1, pluggy-1.6.0 -- /home/ubuntu/.pyenv/versions/3.12.8/bin/python\ncachedir: .pytest_cache\nrootdir: /home/ubuntu/repos/NodeRAG\nconfigfile: pyproject.toml\nplugins: langsmith-0.4.4, rerunfailures-15.1, dash-3.1.1, Faker-18.13.0, anyio-4.8.0, asyncio-0.26.0, cov-6.2.1\nasyncio: mode=Mode.AUTO, asyncio_default_fixture_loop_scope=None, asyncio_default_test_loop_scope=function\ncollecting ... collected 1 item\n\ntests/storage/test_transaction_integration.py::TestTransactionIntegration::test_rollback_on_pinecone_failure FAILED [100%]\n\n=================================== FAILURES ===================================\n_________ TestTransactionIntegration.test_rollback_on_pinecone_failure _________\n../../.pyenv/versions/3.12.8/lib/python3.12/site-packages/pytest_asyncio/plugin.py:549: in runtest\n    super().runtest()\n../../.pyenv/versions/3.12.8/lib/python3.12/site-packages/pytest_asyncio/plugin.py:1066: in inner\n    _loop = _get_event_loop_no_warn()\n            ^^^^^^^^^^^^^^^^^^^^^^^^^\n../../.pyenv/versions/3.12.8/lib/python3.12/site-packages/pytest_asyncio/plugin.py:996: in _get_event_loop_no_warn\n    return asyncio.get_event_loop()\n           ^^^^^^^^^^^^^^^^^^^^^^^^\n../../.pyenv/versions/3.12.8/lib/python3.12/asyncio/events.py:702: in get_event_loop\n    raise RuntimeError('There is no current event loop in thread %r.'\nE   RuntimeError: There is no current event loop in thread 'MainThread'.\n------------------------------ Captured log setup ------------------------------\nERROR    NodeRAG.storage.pinecone_adapter:pinecone_adapter.py:262 Failed to delete namespace txn_test_tenant: (404)\nReason: Not Found\nHTTP response headers: HTTPHeaderDict({'Date': 'Sun, 03 Aug 2025 19:54:23 GMT', 'Content-Type': 'application/json', 'Content-Length': '55', 'Connection': 'keep-alive', 'x-pinecone-request-latency-ms': '3', 'x-pinecone-request-id': '1464459898851394626', 'x-envoy-upstream-service-time': '4', 'server': 'envoy'})\nHTTP response body: {\"code\":5,\"message\":\"Namespace not found\",\"details\":[]}\n---------------------------- Captured log teardown -----------------------------\nERROR    NodeRAG.storage.pinecone_adapter:pinecone_adapter.py:262 Failed to delete namespace txn_test_tenant: (404)\nReason: Not Found\nHTTP response headers: HTTPHeaderDict({'Date': 'Sun, 03 Aug 2025 19:54:23 GMT', 'Content-Type': 'application/json', 'Content-Length': '55', 'Connection': 'keep-alive', 'x-pinecone-request-latency-ms': '2', 'x-pinecone-request-id': '6210593458419645238', 'x-envoy-upstream-service-time': '2', 'server': 'envoy'})\nHTTP response body: {\"code\":5,\"message\":\"Namespace not found\",\"details\":[]}\n=============================== warnings summary ===============================\ntests/storage/test_transaction_integration.py:89\n  /home/ubuntu/repos/NodeRAG/tests/storage/test_transaction_integration.py:89: PytestUnknownMarkWarning: Unknown pytest.mark.integration - is this a typo?  You can register custom marks to avoid this warning - for details, see https://docs.pytest.org/en/stable/how-to/mark.html\n    @pytest.mark.integration\n\n-- Docs: https://docs.pytest.org/en/stable/how-to/capture-warnings.html\n=========================== short test summary info ============================\nFAILED tests/storage/test_transaction_integration.py::TestTransactionIntegration::test_rollback_on_pinecone_failure\n========================= 1 failed, 1 warning in 6.72s =========================\n",
        "stderr": "sys:1: RuntimeWarning: coroutine 'TestTransactionIntegration.test_rollback_on_pinecone_failure' was never awaited\n",
        "error_summary": "RuntimeError: There is no current event loop in thread 'MainThread'."
      },
      {
        "test_path": "tests/storage/test_transaction_integration.py::TestTransactionIntegration::test_consistency_after_multiple_transactions",
        "return_code": 1,
        "passed": false,
        "stdout": "============================= test session starts ==============================\nplatform linux -- Python 3.12.8, pytest-8.4.1, pluggy-1.6.0 -- /home/ubuntu/.pyenv/versions/3.12.8/bin/python\ncachedir: .pytest_cache\nrootdir: /home/ubuntu/repos/NodeRAG\nconfigfile: pyproject.toml\nplugins: langsmith-0.4.4, rerunfailures-15.1, dash-3.1.1, Faker-18.13.0, anyio-4.8.0, asyncio-0.26.0, cov-6.2.1\nasyncio: mode=Mode.AUTO, asyncio_default_fixture_loop_scope=None, asyncio_default_test_loop_scope=function\ncollecting ... collected 1 item\n\ntests/storage/test_transaction_integration.py::TestTransactionIntegration::test_consistency_after_multiple_transactions FAILED [100%]\n\n=================================== FAILURES ===================================\n___ TestTransactionIntegration.test_consistency_after_multiple_transactions ____\n../../.pyenv/versions/3.12.8/lib/python3.12/site-packages/pytest_asyncio/plugin.py:549: in runtest\n    super().runtest()\n../../.pyenv/versions/3.12.8/lib/python3.12/site-packages/pytest_asyncio/plugin.py:1066: in inner\n    _loop = _get_event_loop_no_warn()\n            ^^^^^^^^^^^^^^^^^^^^^^^^^\n../../.pyenv/versions/3.12.8/lib/python3.12/site-packages/pytest_asyncio/plugin.py:996: in _get_event_loop_no_warn\n    return asyncio.get_event_loop()\n           ^^^^^^^^^^^^^^^^^^^^^^^^\n../../.pyenv/versions/3.12.8/lib/python3.12/asyncio/events.py:702: in get_event_loop\n    raise RuntimeError('There is no current event loop in thread %r.'\nE   RuntimeError: There is no current event loop in thread 'MainThread'.\n------------------------------ Captured log setup ------------------------------\nERROR    NodeRAG.storage.pinecone_adapter:pinecone_adapter.py:262 Failed to delete namespace txn_test_tenant: (404)\nReason: Not Found\nHTTP response headers: HTTPHeaderDict({'Date': 'Sun, 03 Aug 2025 19:54:32 GMT', 'Content-Type': 'application/json', 'Content-Length': '55', 'Connection': 'keep-alive', 'x-pinecone-request-latency-ms': '2', 'x-pinecone-request-id': '5588175720254722017', 'x-envoy-upstream-service-time': '3', 'server': 'envoy'})\nHTTP response body: {\"code\":5,\"message\":\"Namespace not found\",\"details\":[]}\n---------------------------- Captured log teardown -----------------------------\nERROR    NodeRAG.storage.pinecone_adapter:pinecone_adapter.py:262 Failed to delete namespace txn_test_tenant: (404)\nReason: Not Found\nHTTP response headers: HTTPHeaderDict({'Date': 'Sun, 03 Aug 2025 19:54:32 GMT', 'Content-Type': 'application/json', 'Content-Length': '55', 'Connection': 'keep-alive', 'x-pinecone-request-latency-ms': '2', 'x-pinecone-request-id': '6834639196032553472', 'x-envoy-upstream-service-time': '2', 'server': 'envoy'})\nHTTP response body: {\"code\":5,\"message\":\"Namespace not found\",\"details\":[]}\n=============================== warnings summary ===============================\ntests/storage/test_transaction_integration.py:89\n  /home/ubuntu/repos/NodeRAG/tests/storage/test_transaction_integration.py:89: PytestUnknownMarkWarning: Unknown pytest.mark.integration - is this a typo?  You can register custom marks to avoid this warning - for details, see https://docs.pytest.org/en/stable/how-to/mark.html\n    @pytest.mark.integration\n\n-- Docs: https://docs.pytest.org/en/stable/how-to/capture-warnings.html\n=========================== short test summary info ============================\nFAILED tests/storage/test_transaction_integration.py::TestTransactionIntegration::test_consistency_after_multiple_transactions\n========================= 1 failed, 1 warning in 6.54s =========================\n",
        "stderr": "sys:1: RuntimeWarning: coroutine 'TestTransactionIntegration.test_consistency_after_multiple_transactions' was never awaited\n",
        "error_summary": "RuntimeError: There is no current event loop in thread 'MainThread'."
      }
    ],
    "transaction_other": [],
    "other": []
  },
  "all_test_results": [
    {
      "test_path": "tests/storage/test_neo4j_adapter.py::TestNeo4jAdapter::test_clear_tenant_data",
      "return_code": 1,
      "passed": false,
      "stdout": "============================= test session starts ==============================\nplatform linux -- Python 3.12.8, pytest-8.4.1, pluggy-1.6.0 -- /home/ubuntu/.pyenv/versions/3.12.8/bin/python\ncachedir: .pytest_cache\nrootdir: /home/ubuntu/repos/NodeRAG\nconfigfile: pyproject.toml\nplugins: langsmith-0.4.4, rerunfailures-15.1, dash-3.1.1, Faker-18.13.0, anyio-4.8.0, asyncio-0.26.0, cov-6.2.1\nasyncio: mode=Mode.AUTO, asyncio_default_fixture_loop_scope=None, asyncio_default_test_loop_scope=function\ncollecting ... collected 1 item\n\ntests/storage/test_neo4j_adapter.py::TestNeo4jAdapter::test_clear_tenant_data FAILED [100%]\n\n=================================== FAILURES ===================================\n___________________ TestNeo4jAdapter.test_clear_tenant_data ____________________\ntests/storage/test_neo4j_adapter.py:212: in test_clear_tenant_data\n    assert success is True\nE   assert (0, 0) is True\n=========================== short test summary info ============================\nFAILED tests/storage/test_neo4j_adapter.py::TestNeo4jAdapter::test_clear_tenant_data\n============================== 1 failed in 4.75s ===============================\n",
      "stderr": "",
      "error_summary": "assert success is True"
    },
    {
      "test_path": "tests/storage/test_neo4j_adapter.py::TestNeo4jAdapter::test_add_nodes_batch",
      "return_code": 0,
      "passed": true,
      "stdout": "============================= test session starts ==============================\nplatform linux -- Python 3.12.8, pytest-8.4.1, pluggy-1.6.0 -- /home/ubuntu/.pyenv/versions/3.12.8/bin/python\ncachedir: .pytest_cache\nrootdir: /home/ubuntu/repos/NodeRAG\nconfigfile: pyproject.toml\nplugins: langsmith-0.4.4, rerunfailures-15.1, dash-3.1.1, Faker-18.13.0, anyio-4.8.0, asyncio-0.26.0, cov-6.2.1\nasyncio: mode=Mode.AUTO, asyncio_default_fixture_loop_scope=None, asyncio_default_test_loop_scope=function\ncollecting ... collected 1 item\n\ntests/storage/test_neo4j_adapter.py::TestNeo4jAdapter::test_add_nodes_batch PASSED [100%]\n\n============================== 1 passed in 4.20s ===============================\n",
      "stderr": "",
      "error_summary": "No specific error pattern found"
    },
    {
      "test_path": "tests/storage/test_neo4j_adapter.py::TestNeo4jAdapter::test_statistics",
      "return_code": 0,
      "passed": true,
      "stdout": "============================= test session starts ==============================\nplatform linux -- Python 3.12.8, pytest-8.4.1, pluggy-1.6.0 -- /home/ubuntu/.pyenv/versions/3.12.8/bin/python\ncachedir: .pytest_cache\nrootdir: /home/ubuntu/repos/NodeRAG\nconfigfile: pyproject.toml\nplugins: langsmith-0.4.4, rerunfailures-15.1, dash-3.1.1, Faker-18.13.0, anyio-4.8.0, asyncio-0.26.0, cov-6.2.1\nasyncio: mode=Mode.AUTO, asyncio_default_fixture_loop_scope=None, asyncio_default_test_loop_scope=function\ncollecting ... collected 1 item\n\ntests/storage/test_neo4j_adapter.py::TestNeo4jAdapter::test_statistics PASSED [100%]\n\n============================== 1 passed in 4.47s ===============================\n",
      "stderr": "",
      "error_summary": "No specific error pattern found"
    },
    {
      "test_path": "tests/storage/test_neo4j_adapter.py::TestNeo4jAdapter::test_connection",
      "return_code": 0,
      "passed": true,
      "stdout": "============================= test session starts ==============================\nplatform linux -- Python 3.12.8, pytest-8.4.1, pluggy-1.6.0 -- /home/ubuntu/.pyenv/versions/3.12.8/bin/python\ncachedir: .pytest_cache\nrootdir: /home/ubuntu/repos/NodeRAG\nconfigfile: pyproject.toml\nplugins: langsmith-0.4.4, rerunfailures-15.1, dash-3.1.1, Faker-18.13.0, anyio-4.8.0, asyncio-0.26.0, cov-6.2.1\nasyncio: mode=Mode.AUTO, asyncio_default_fixture_loop_scope=None, asyncio_default_test_loop_scope=function\ncollecting ... collected 1 item\n\ntests/storage/test_neo4j_adapter.py::TestNeo4jAdapter::test_connection PASSED [100%]\n\n============================== 1 passed in 4.18s ===============================\n",
      "stderr": "",
      "error_summary": "No specific error pattern found"
    },
    {
      "test_path": "tests/storage/test_pinecone_adapter.py::TestPineconeAdapter::test_namespace_cleanup",
      "return_code": 0,
      "passed": true,
      "stdout": "============================= test session starts ==============================\nplatform linux -- Python 3.12.8, pytest-8.4.1, pluggy-1.6.0 -- /home/ubuntu/.pyenv/versions/3.12.8/bin/python\ncachedir: .pytest_cache\nrootdir: /home/ubuntu/repos/NodeRAG\nconfigfile: pyproject.toml\nplugins: langsmith-0.4.4, rerunfailures-15.1, dash-3.1.1, Faker-18.13.0, anyio-4.8.0, asyncio-0.26.0, cov-6.2.1\nasyncio: mode=Mode.AUTO, asyncio_default_fixture_loop_scope=None, asyncio_default_test_loop_scope=function\ncollecting ... collected 1 item\n\ntests/storage/test_pinecone_adapter.py::TestPineconeAdapter::test_namespace_cleanup PASSED [100%]\n\n============================== 1 passed in 17.04s ==============================\n",
      "stderr": "",
      "error_summary": "No specific error pattern found"
    },
    {
      "test_path": "tests/storage/test_pinecone_adapter.py::TestPineconeAdapter::test_delete_vectors",
      "return_code": 0,
      "passed": true,
      "stdout": "============================= test session starts ==============================\nplatform linux -- Python 3.12.8, pytest-8.4.1, pluggy-1.6.0 -- /home/ubuntu/.pyenv/versions/3.12.8/bin/python\ncachedir: .pytest_cache\nrootdir: /home/ubuntu/repos/NodeRAG\nconfigfile: pyproject.toml\nplugins: langsmith-0.4.4, rerunfailures-15.1, dash-3.1.1, Faker-18.13.0, anyio-4.8.0, asyncio-0.26.0, cov-6.2.1\nasyncio: mode=Mode.AUTO, asyncio_default_fixture_loop_scope=None, asyncio_default_test_loop_scope=function\ncollecting ... collected 1 item\n\ntests/storage/test_pinecone_adapter.py::TestPineconeAdapter::test_delete_vectors PASSED [100%]\n\n============================== 1 passed in 16.61s ==============================\n",
      "stderr": "",
      "error_summary": "No specific error pattern found"
    },
    {
      "test_path": "tests/storage/test_pinecone_adapter.py::TestPineconeAdapter::test_search_with_filters",
      "return_code": 1,
      "passed": false,
      "stdout": "============================= test session starts ==============================\nplatform linux -- Python 3.12.8, pytest-8.4.1, pluggy-1.6.0 -- /home/ubuntu/.pyenv/versions/3.12.8/bin/python\ncachedir: .pytest_cache\nrootdir: /home/ubuntu/repos/NodeRAG\nconfigfile: pyproject.toml\nplugins: langsmith-0.4.4, rerunfailures-15.1, dash-3.1.1, Faker-18.13.0, anyio-4.8.0, asyncio-0.26.0, cov-6.2.1\nasyncio: mode=Mode.AUTO, asyncio_default_fixture_loop_scope=None, asyncio_default_test_loop_scope=function\ncollecting ... collected 1 item\n\ntests/storage/test_pinecone_adapter.py::TestPineconeAdapter::test_search_with_filters FAILED [100%]\n\n=================================== FAILURES ===================================\n_________________ TestPineconeAdapter.test_search_with_filters _________________\ntests/storage/test_pinecone_adapter.py:211: in test_search_with_filters\n    assert len(results) >= 1\nE   assert 0 >= 1\nE    +  where 0 = len([])\n----------------------------- Captured stdout call -----------------------------\nSearch results: []\nLooking for vector1_id: search_test_1\nSearch filters: tenant_id=test_tenant, interaction_type=email\nAll results in test_tenant: []\n---------------------------- Captured log teardown -----------------------------\nERROR    NodeRAG.storage.pinecone_adapter:pinecone_adapter.py:262 Failed to delete namespace test_tenant_1: (404)\nReason: Not Found\nHTTP response headers: HTTPHeaderDict({'Date': 'Sun, 03 Aug 2025 19:53:39 GMT', 'Content-Type': 'application/json', 'Content-Length': '55', 'Connection': 'keep-alive', 'x-pinecone-request-latency-ms': '1', 'x-pinecone-request-id': '6994322872857428948', 'x-envoy-upstream-service-time': '2', 'server': 'envoy'})\nHTTP response body: {\"code\":5,\"message\":\"Namespace not found\",\"details\":[]}\n\nERROR    NodeRAG.storage.pinecone_adapter:pinecone_adapter.py:262 Failed to delete namespace test_tenant_2: (404)\nReason: Not Found\nHTTP response headers: HTTPHeaderDict({'Date': 'Sun, 03 Aug 2025 19:53:39 GMT', 'Content-Type': 'application/json', 'Content-Length': '55', 'Connection': 'keep-alive', 'x-pinecone-request-latency-ms': '2', 'x-pinecone-request-id': '6051191404995970916', 'x-envoy-upstream-service-time': '2', 'server': 'envoy'})\nHTTP response body: {\"code\":5,\"message\":\"Namespace not found\",\"details\":[]}\n=========================== short test summary info ============================\nFAILED tests/storage/test_pinecone_adapter.py::TestPineconeAdapter::test_search_with_filters\n============================== 1 failed in 23.79s ==============================\n",
      "stderr": "",
      "error_summary": "Namespace not found"
    },
    {
      "test_path": "tests/storage/test_pinecone_adapter.py::TestPineconeAdapter::test_upsert_vectors",
      "return_code": 4,
      "passed": false,
      "stdout": "============================= test session starts ==============================\nplatform linux -- Python 3.12.8, pytest-8.4.1, pluggy-1.6.0 -- /home/ubuntu/.pyenv/versions/3.12.8/bin/python\ncachedir: .pytest_cache\nrootdir: /home/ubuntu/repos/NodeRAG\nconfigfile: pyproject.toml\nplugins: langsmith-0.4.4, rerunfailures-15.1, dash-3.1.1, Faker-18.13.0, anyio-4.8.0, asyncio-0.26.0, cov-6.2.1\nasyncio: mode=Mode.AUTO, asyncio_default_fixture_loop_scope=None, asyncio_default_test_loop_scope=function\ncollecting ... collected 0 items\n\n============================ no tests ran in 2.21s =============================\n",
      "stderr": "ERROR: not found: /home/ubuntu/repos/NodeRAG/tests/storage/test_pinecone_adapter.py::TestPineconeAdapter::test_upsert_vectors\n(no match in any of [<Class TestPineconeAdapter>])\n\n",
      "error_summary": "No specific error pattern found"
    },
    {
      "test_path": "tests/storage/test_transaction_manager.py::TestTransactionManager::test_rollback_with_mock_adapters",
      "return_code": 0,
      "passed": true,
      "stdout": "============================= test session starts ==============================\nplatform linux -- Python 3.12.8, pytest-8.4.1, pluggy-1.6.0 -- /home/ubuntu/.pyenv/versions/3.12.8/bin/python\ncachedir: .pytest_cache\nrootdir: /home/ubuntu/repos/NodeRAG\nconfigfile: pyproject.toml\nplugins: langsmith-0.4.4, rerunfailures-15.1, dash-3.1.1, Faker-18.13.0, anyio-4.8.0, asyncio-0.26.0, cov-6.2.1\nasyncio: mode=Mode.AUTO, asyncio_default_fixture_loop_scope=None, asyncio_default_test_loop_scope=function\ncollecting ... collected 1 item\n\ntests/storage/test_transaction_manager.py::TestTransactionManager::test_rollback_with_mock_adapters PASSED [100%]\n\n============================== 1 passed in 2.24s ===============================\n",
      "stderr": "",
      "error_summary": "No specific error pattern found"
    },
    {
      "test_path": "tests/storage/test_transaction_manager.py::TestTransactionManager::test_batch_operations_success",
      "return_code": 0,
      "passed": true,
      "stdout": "============================= test session starts ==============================\nplatform linux -- Python 3.12.8, pytest-8.4.1, pluggy-1.6.0 -- /home/ubuntu/.pyenv/versions/3.12.8/bin/python\ncachedir: .pytest_cache\nrootdir: /home/ubuntu/repos/NodeRAG\nconfigfile: pyproject.toml\nplugins: langsmith-0.4.4, rerunfailures-15.1, dash-3.1.1, Faker-18.13.0, anyio-4.8.0, asyncio-0.26.0, cov-6.2.1\nasyncio: mode=Mode.AUTO, asyncio_default_fixture_loop_scope=None, asyncio_default_test_loop_scope=function\ncollecting ... collected 1 item\n\ntests/storage/test_transaction_manager.py::TestTransactionManager::test_batch_operations_success PASSED [100%]\n\n============================== 1 passed in 2.25s ===============================\n",
      "stderr": "",
      "error_summary": "No specific error pattern found"
    },
    {
      "test_path": "tests/storage/test_transaction_manager.py::TestTransactionManager::test_concurrent_transactions",
      "return_code": 0,
      "passed": true,
      "stdout": "============================= test session starts ==============================\nplatform linux -- Python 3.12.8, pytest-8.4.1, pluggy-1.6.0 -- /home/ubuntu/.pyenv/versions/3.12.8/bin/python\ncachedir: .pytest_cache\nrootdir: /home/ubuntu/repos/NodeRAG\nconfigfile: pyproject.toml\nplugins: langsmith-0.4.4, rerunfailures-15.1, dash-3.1.1, Faker-18.13.0, anyio-4.8.0, asyncio-0.26.0, cov-6.2.1\nasyncio: mode=Mode.AUTO, asyncio_default_fixture_loop_scope=None, asyncio_default_test_loop_scope=function\ncollecting ... collected 1 item\n\ntests/storage/test_transaction_manager.py::TestTransactionManager::test_concurrent_transactions PASSED [100%]\n\n============================== 1 passed in 2.23s ===============================\n",
      "stderr": "",
      "error_summary": "No specific error pattern found"
    },
    {
      "test_path": "tests/storage/test_transaction_integration.py::TestTransactionIntegration::test_successful_node_and_embedding_creation",
      "return_code": 1,
      "passed": false,
      "stdout": "============================= test session starts ==============================\nplatform linux -- Python 3.12.8, pytest-8.4.1, pluggy-1.6.0 -- /home/ubuntu/.pyenv/versions/3.12.8/bin/python\ncachedir: .pytest_cache\nrootdir: /home/ubuntu/repos/NodeRAG\nconfigfile: pyproject.toml\nplugins: langsmith-0.4.4, rerunfailures-15.1, dash-3.1.1, Faker-18.13.0, anyio-4.8.0, asyncio-0.26.0, cov-6.2.1\nasyncio: mode=Mode.AUTO, asyncio_default_fixture_loop_scope=None, asyncio_default_test_loop_scope=function\ncollecting ... collected 1 item\n\ntests/storage/test_transaction_integration.py::TestTransactionIntegration::test_successful_node_and_embedding_creation FAILED [100%]\n\n=================================== FAILURES ===================================\n____ TestTransactionIntegration.test_successful_node_and_embedding_creation ____\n../../.pyenv/versions/3.12.8/lib/python3.12/site-packages/pytest_asyncio/plugin.py:549: in runtest\n    super().runtest()\n../../.pyenv/versions/3.12.8/lib/python3.12/site-packages/pytest_asyncio/plugin.py:1066: in inner\n    _loop = _get_event_loop_no_warn()\n            ^^^^^^^^^^^^^^^^^^^^^^^^^\n../../.pyenv/versions/3.12.8/lib/python3.12/site-packages/pytest_asyncio/plugin.py:996: in _get_event_loop_no_warn\n    return asyncio.get_event_loop()\n           ^^^^^^^^^^^^^^^^^^^^^^^^\n../../.pyenv/versions/3.12.8/lib/python3.12/asyncio/events.py:702: in get_event_loop\n    raise RuntimeError('There is no current event loop in thread %r.'\nE   RuntimeError: There is no current event loop in thread 'MainThread'.\n------------------------------ Captured log setup ------------------------------\nERROR    NodeRAG.storage.pinecone_adapter:pinecone_adapter.py:262 Failed to delete namespace txn_test_tenant: (404)\nReason: Not Found\nHTTP response headers: HTTPHeaderDict({'Date': 'Sun, 03 Aug 2025 19:54:04 GMT', 'Content-Type': 'application/json', 'Content-Length': '55', 'Connection': 'keep-alive', 'x-pinecone-request-latency-ms': '23', 'x-pinecone-request-id': '4418735150012489711', 'x-envoy-upstream-service-time': '24', 'server': 'envoy'})\nHTTP response body: {\"code\":5,\"message\":\"Namespace not found\",\"details\":[]}\n---------------------------- Captured log teardown -----------------------------\nERROR    NodeRAG.storage.pinecone_adapter:pinecone_adapter.py:262 Failed to delete namespace txn_test_tenant: (404)\nReason: Not Found\nHTTP response headers: HTTPHeaderDict({'Date': 'Sun, 03 Aug 2025 19:54:04 GMT', 'Content-Type': 'application/json', 'Content-Length': '55', 'Connection': 'keep-alive', 'x-pinecone-request-latency-ms': '19', 'x-pinecone-request-id': '8894724315327290894', 'x-envoy-upstream-service-time': '19', 'server': 'envoy'})\nHTTP response body: {\"code\":5,\"message\":\"Namespace not found\",\"details\":[]}\n=============================== warnings summary ===============================\ntests/storage/test_transaction_integration.py:89\n  /home/ubuntu/repos/NodeRAG/tests/storage/test_transaction_integration.py:89: PytestUnknownMarkWarning: Unknown pytest.mark.integration - is this a typo?  You can register custom marks to avoid this warning - for details, see https://docs.pytest.org/en/stable/how-to/mark.html\n    @pytest.mark.integration\n\n-- Docs: https://docs.pytest.org/en/stable/how-to/capture-warnings.html\n=========================== short test summary info ============================\nFAILED tests/storage/test_transaction_integration.py::TestTransactionIntegration::test_successful_node_and_embedding_creation\n========================= 1 failed, 1 warning in 4.70s =========================\n",
      "stderr": "sys:1: RuntimeWarning: coroutine 'TestTransactionIntegration.test_successful_node_and_embedding_creation' was never awaited\n",
      "error_summary": "RuntimeError: There is no current event loop in thread 'MainThread'."
    },
    {
      "test_path": "tests/storage/test_transaction_integration.py::TestTransactionIntegration::test_batch_transaction_success",
      "return_code": 1,
      "passed": false,
      "stdout": "============================= test session starts ==============================\nplatform linux -- Python 3.12.8, pytest-8.4.1, pluggy-1.6.0 -- /home/ubuntu/.pyenv/versions/3.12.8/bin/python\ncachedir: .pytest_cache\nrootdir: /home/ubuntu/repos/NodeRAG\nconfigfile: pyproject.toml\nplugins: langsmith-0.4.4, rerunfailures-15.1, dash-3.1.1, Faker-18.13.0, anyio-4.8.0, asyncio-0.26.0, cov-6.2.1\nasyncio: mode=Mode.AUTO, asyncio_default_fixture_loop_scope=None, asyncio_default_test_loop_scope=function\ncollecting ... collected 1 item\n\ntests/storage/test_transaction_integration.py::TestTransactionIntegration::test_batch_transaction_success FAILED [100%]\n\n=================================== FAILURES ===================================\n__________ TestTransactionIntegration.test_batch_transaction_success ___________\n../../.pyenv/versions/3.12.8/lib/python3.12/site-packages/pytest_asyncio/plugin.py:549: in runtest\n    super().runtest()\n../../.pyenv/versions/3.12.8/lib/python3.12/site-packages/pytest_asyncio/plugin.py:1066: in inner\n    _loop = _get_event_loop_no_warn()\n            ^^^^^^^^^^^^^^^^^^^^^^^^^\n../../.pyenv/versions/3.12.8/lib/python3.12/site-packages/pytest_asyncio/plugin.py:996: in _get_event_loop_no_warn\n    return asyncio.get_event_loop()\n           ^^^^^^^^^^^^^^^^^^^^^^^^\n../../.pyenv/versions/3.12.8/lib/python3.12/asyncio/events.py:702: in get_event_loop\n    raise RuntimeError('There is no current event loop in thread %r.'\nE   RuntimeError: There is no current event loop in thread 'MainThread'.\n------------------------------ Captured log setup ------------------------------\nERROR    NodeRAG.storage.pinecone_adapter:pinecone_adapter.py:262 Failed to delete namespace txn_test_tenant: (404)\nReason: Not Found\nHTTP response headers: HTTPHeaderDict({'Date': 'Sun, 03 Aug 2025 19:54:14 GMT', 'Content-Type': 'application/json', 'Content-Length': '55', 'Connection': 'keep-alive', 'x-pinecone-request-latency-ms': '1', 'x-pinecone-request-id': '1675310034042861668', 'x-envoy-upstream-service-time': '2', 'server': 'envoy'})\nHTTP response body: {\"code\":5,\"message\":\"Namespace not found\",\"details\":[]}\n---------------------------- Captured log teardown -----------------------------\nERROR    NodeRAG.storage.pinecone_adapter:pinecone_adapter.py:262 Failed to delete namespace txn_test_tenant: (404)\nReason: Not Found\nHTTP response headers: HTTPHeaderDict({'Date': 'Sun, 03 Aug 2025 19:54:14 GMT', 'Content-Type': 'application/json', 'Content-Length': '55', 'Connection': 'keep-alive', 'x-pinecone-request-latency-ms': '3', 'x-pinecone-request-id': '9147613141540617540', 'x-envoy-upstream-service-time': '4', 'server': 'envoy'})\nHTTP response body: {\"code\":5,\"message\":\"Namespace not found\",\"details\":[]}\n=============================== warnings summary ===============================\ntests/storage/test_transaction_integration.py:89\n  /home/ubuntu/repos/NodeRAG/tests/storage/test_transaction_integration.py:89: PytestUnknownMarkWarning: Unknown pytest.mark.integration - is this a typo?  You can register custom marks to avoid this warning - for details, see https://docs.pytest.org/en/stable/how-to/mark.html\n    @pytest.mark.integration\n\n-- Docs: https://docs.pytest.org/en/stable/how-to/capture-warnings.html\n=========================== short test summary info ============================\nFAILED tests/storage/test_transaction_integration.py::TestTransactionIntegration::test_batch_transaction_success\n========================= 1 failed, 1 warning in 7.23s =========================\n",
      "stderr": "sys:1: RuntimeWarning: coroutine 'TestTransactionIntegration.test_batch_transaction_success' was never awaited\n",
      "error_summary": "RuntimeError: There is no current event loop in thread 'MainThread'."
    },
    {
      "test_path": "tests/storage/test_transaction_integration.py::TestTransactionIntegration::test_rollback_on_pinecone_failure",
      "return_code": 1,
      "passed": false,
      "stdout": "============================= test session starts ==============================\nplatform linux -- Python 3.12.8, pytest-8.4.1, pluggy-1.6.0 -- /home/ubuntu/.pyenv/versions/3.12.8/bin/python\ncachedir: .pytest_cache\nrootdir: /home/ubuntu/repos/NodeRAG\nconfigfile: pyproject.toml\nplugins: langsmith-0.4.4, rerunfailures-15.1, dash-3.1.1, Faker-18.13.0, anyio-4.8.0, asyncio-0.26.0, cov-6.2.1\nasyncio: mode=Mode.AUTO, asyncio_default_fixture_loop_scope=None, asyncio_default_test_loop_scope=function\ncollecting ... collected 1 item\n\ntests/storage/test_transaction_integration.py::TestTransactionIntegration::test_rollback_on_pinecone_failure FAILED [100%]\n\n=================================== FAILURES ===================================\n_________ TestTransactionIntegration.test_rollback_on_pinecone_failure _________\n../../.pyenv/versions/3.12.8/lib/python3.12/site-packages/pytest_asyncio/plugin.py:549: in runtest\n    super().runtest()\n../../.pyenv/versions/3.12.8/lib/python3.12/site-packages/pytest_asyncio/plugin.py:1066: in inner\n    _loop = _get_event_loop_no_warn()\n            ^^^^^^^^^^^^^^^^^^^^^^^^^\n../../.pyenv/versions/3.12.8/lib/python3.12/site-packages/pytest_asyncio/plugin.py:996: in _get_event_loop_no_warn\n    return asyncio.get_event_loop()\n           ^^^^^^^^^^^^^^^^^^^^^^^^\n../../.pyenv/versions/3.12.8/lib/python3.12/asyncio/events.py:702: in get_event_loop\n    raise RuntimeError('There is no current event loop in thread %r.'\nE   RuntimeError: There is no current event loop in thread 'MainThread'.\n------------------------------ Captured log setup ------------------------------\nERROR    NodeRAG.storage.pinecone_adapter:pinecone_adapter.py:262 Failed to delete namespace txn_test_tenant: (404)\nReason: Not Found\nHTTP response headers: HTTPHeaderDict({'Date': 'Sun, 03 Aug 2025 19:54:23 GMT', 'Content-Type': 'application/json', 'Content-Length': '55', 'Connection': 'keep-alive', 'x-pinecone-request-latency-ms': '3', 'x-pinecone-request-id': '1464459898851394626', 'x-envoy-upstream-service-time': '4', 'server': 'envoy'})\nHTTP response body: {\"code\":5,\"message\":\"Namespace not found\",\"details\":[]}\n---------------------------- Captured log teardown -----------------------------\nERROR    NodeRAG.storage.pinecone_adapter:pinecone_adapter.py:262 Failed to delete namespace txn_test_tenant: (404)\nReason: Not Found\nHTTP response headers: HTTPHeaderDict({'Date': 'Sun, 03 Aug 2025 19:54:23 GMT', 'Content-Type': 'application/json', 'Content-Length': '55', 'Connection': 'keep-alive', 'x-pinecone-request-latency-ms': '2', 'x-pinecone-request-id': '6210593458419645238', 'x-envoy-upstream-service-time': '2', 'server': 'envoy'})\nHTTP response body: {\"code\":5,\"message\":\"Namespace not found\",\"details\":[]}\n=============================== warnings summary ===============================\ntests/storage/test_transaction_integration.py:89\n  /home/ubuntu/repos/NodeRAG/tests/storage/test_transaction_integration.py:89: PytestUnknownMarkWarning: Unknown pytest.mark.integration - is this a typo?  You can register custom marks to avoid this warning - for details, see https://docs.pytest.org/en/stable/how-to/mark.html\n    @pytest.mark.integration\n\n-- Docs: https://docs.pytest.org/en/stable/how-to/capture-warnings.html\n=========================== short test summary info ============================\nFAILED tests/storage/test_transaction_integration.py::TestTransactionIntegration::test_rollback_on_pinecone_failure\n========================= 1 failed, 1 warning in 6.72s =========================\n",
      "stderr": "sys:1: RuntimeWarning: coroutine 'TestTransactionIntegration.test_rollback_on_pinecone_failure' was never awaited\n",
      "error_summary": "RuntimeError: There is no current event loop in thread 'MainThread'."
    },
    {
      "test_path": "tests/storage/test_transaction_integration.py::TestTransactionIntegration::test_consistency_after_multiple_transactions",
      "return_code": 1,
      "passed": false,
      "stdout": "============================= test session starts ==============================\nplatform linux -- Python 3.12.8, pytest-8.4.1, pluggy-1.6.0 -- /home/ubuntu/.pyenv/versions/3.12.8/bin/python\ncachedir: .pytest_cache\nrootdir: /home/ubuntu/repos/NodeRAG\nconfigfile: pyproject.toml\nplugins: langsmith-0.4.4, rerunfailures-15.1, dash-3.1.1, Faker-18.13.0, anyio-4.8.0, asyncio-0.26.0, cov-6.2.1\nasyncio: mode=Mode.AUTO, asyncio_default_fixture_loop_scope=None, asyncio_default_test_loop_scope=function\ncollecting ... collected 1 item\n\ntests/storage/test_transaction_integration.py::TestTransactionIntegration::test_consistency_after_multiple_transactions FAILED [100%]\n\n=================================== FAILURES ===================================\n___ TestTransactionIntegration.test_consistency_after_multiple_transactions ____\n../../.pyenv/versions/3.12.8/lib/python3.12/site-packages/pytest_asyncio/plugin.py:549: in runtest\n    super().runtest()\n../../.pyenv/versions/3.12.8/lib/python3.12/site-packages/pytest_asyncio/plugin.py:1066: in inner\n    _loop = _get_event_loop_no_warn()\n            ^^^^^^^^^^^^^^^^^^^^^^^^^\n../../.pyenv/versions/3.12.8/lib/python3.12/site-packages/pytest_asyncio/plugin.py:996: in _get_event_loop_no_warn\n    return asyncio.get_event_loop()\n           ^^^^^^^^^^^^^^^^^^^^^^^^\n../../.pyenv/versions/3.12.8/lib/python3.12/asyncio/events.py:702: in get_event_loop\n    raise RuntimeError('There is no current event loop in thread %r.'\nE   RuntimeError: There is no current event loop in thread 'MainThread'.\n------------------------------ Captured log setup ------------------------------\nERROR    NodeRAG.storage.pinecone_adapter:pinecone_adapter.py:262 Failed to delete namespace txn_test_tenant: (404)\nReason: Not Found\nHTTP response headers: HTTPHeaderDict({'Date': 'Sun, 03 Aug 2025 19:54:32 GMT', 'Content-Type': 'application/json', 'Content-Length': '55', 'Connection': 'keep-alive', 'x-pinecone-request-latency-ms': '2', 'x-pinecone-request-id': '5588175720254722017', 'x-envoy-upstream-service-time': '3', 'server': 'envoy'})\nHTTP response body: {\"code\":5,\"message\":\"Namespace not found\",\"details\":[]}\n---------------------------- Captured log teardown -----------------------------\nERROR    NodeRAG.storage.pinecone_adapter:pinecone_adapter.py:262 Failed to delete namespace txn_test_tenant: (404)\nReason: Not Found\nHTTP response headers: HTTPHeaderDict({'Date': 'Sun, 03 Aug 2025 19:54:32 GMT', 'Content-Type': 'application/json', 'Content-Length': '55', 'Connection': 'keep-alive', 'x-pinecone-request-latency-ms': '2', 'x-pinecone-request-id': '6834639196032553472', 'x-envoy-upstream-service-time': '2', 'server': 'envoy'})\nHTTP response body: {\"code\":5,\"message\":\"Namespace not found\",\"details\":[]}\n=============================== warnings summary ===============================\ntests/storage/test_transaction_integration.py:89\n  /home/ubuntu/repos/NodeRAG/tests/storage/test_transaction_integration.py:89: PytestUnknownMarkWarning: Unknown pytest.mark.integration - is this a typo?  You can register custom marks to avoid this warning - for details, see https://docs.pytest.org/en/stable/how-to/mark.html\n    @pytest.mark.integration\n\n-- Docs: https://docs.pytest.org/en/stable/how-to/capture-warnings.html\n=========================== short test summary info ============================\nFAILED tests/storage/test_transaction_integration.py::TestTransactionIntegration::test_consistency_after_multiple_transactions\n========================= 1 failed, 1 warning in 6.54s =========================\n",
      "stderr": "sys:1: RuntimeWarning: coroutine 'TestTransactionIntegration.test_consistency_after_multiple_transactions' was never awaited\n",
      "error_summary": "RuntimeError: There is no current event loop in thread 'MainThread'."
    },
    {
      "test_path": "tests/storage/test_transaction_fixes.py::test_data_consistency_maintained",
      "return_code": 0,
      "passed": true,
      "stdout": "============================= test session starts ==============================\nplatform linux -- Python 3.12.8, pytest-8.4.1, pluggy-1.6.0 -- /home/ubuntu/.pyenv/versions/3.12.8/bin/python\ncachedir: .pytest_cache\nrootdir: /home/ubuntu/repos/NodeRAG\nconfigfile: pyproject.toml\nplugins: langsmith-0.4.4, rerunfailures-15.1, dash-3.1.1, Faker-18.13.0, anyio-4.8.0, asyncio-0.26.0, cov-6.2.1\nasyncio: mode=Mode.AUTO, asyncio_default_fixture_loop_scope=None, asyncio_default_test_loop_scope=function\ncollecting ... collected 1 item\n\ntests/storage/test_transaction_fixes.py::test_data_consistency_maintained PASSED [100%]\n\n============================== 1 passed in 12.03s ==============================\n",
      "stderr": "",
      "error_summary": "No specific error pattern found"
    },
    {
      "test_path": "tests/integration/test_pinecone_integration.py",
      "return_code": -1,
      "passed": false,
      "stdout": "",
      "stderr": "Test timed out after 30 seconds",
      "error_summary": "Test timeout - likely connection or hanging issue"
    },
    {
      "test_path": "tests/integration/test_neo4j_integration.py",
      "return_code": 0,
      "passed": true,
      "stdout": "============================= test session starts ==============================\nplatform linux -- Python 3.12.8, pytest-8.4.1, pluggy-1.6.0 -- /home/ubuntu/.pyenv/versions/3.12.8/bin/python\ncachedir: .pytest_cache\nrootdir: /home/ubuntu/repos/NodeRAG\nconfigfile: pyproject.toml\nplugins: langsmith-0.4.4, rerunfailures-15.1, dash-3.1.1, Faker-18.13.0, anyio-4.8.0, asyncio-0.26.0, cov-6.2.1\nasyncio: mode=Mode.AUTO, asyncio_default_fixture_loop_scope=None, asyncio_default_test_loop_scope=function\ncollecting ... collected 4 items\n\ntests/integration/test_neo4j_integration.py::TestNeo4jIntegration::test_batch_performance PASSED [ 25%]\ntests/integration/test_neo4j_integration.py::TestNeo4jIntegration::test_complete_workflow_with_eq_metadata PASSED [ 50%]\ntests/integration/test_neo4j_integration.py::TestNeo4jIntegration::test_index_usage_verification PASSED [ 75%]\ntests/integration/test_neo4j_integration.py::TestNeo4jIntegration::test_connection_resilience PASSED [100%]\n\n=============================== warnings summary ===============================\ntests/integration/test_neo4j_integration.py:34\n  /home/ubuntu/repos/NodeRAG/tests/integration/test_neo4j_integration.py:34: PytestUnknownMarkWarning: Unknown pytest.mark.integration - is this a typo?  You can register custom marks to avoid this warning - for details, see https://docs.pytest.org/en/stable/how-to/mark.html\n    @pytest.mark.integration\n\n-- Docs: https://docs.pytest.org/en/stable/how-to/capture-warnings.html\n======================== 4 passed, 1 warning in 13.52s =========================\n",
      "stderr": "",
      "error_summary": "No specific error pattern found"
    }
  ],
  "exact_failing_tests": [
    "tests/storage/test_neo4j_adapter.py::TestNeo4jAdapter::test_clear_tenant_data",
    "tests/storage/test_pinecone_adapter.py::TestPineconeAdapter::test_search_with_filters",
    "tests/storage/test_pinecone_adapter.py::TestPineconeAdapter::test_upsert_vectors",
    "tests/storage/test_transaction_integration.py::TestTransactionIntegration::test_successful_node_and_embedding_creation",
    "tests/storage/test_transaction_integration.py::TestTransactionIntegration::test_batch_transaction_success",
    "tests/storage/test_transaction_integration.py::TestTransactionIntegration::test_rollback_on_pinecone_failure",
    "tests/storage/test_transaction_integration.py::TestTransactionIntegration::test_consistency_after_multiple_transactions",
    "tests/integration/test_pinecone_integration.py"
  ]
}